Workbook

Sheet PRICELIST
B2: SKU CODING | I2: SKU | J2: CATEGORY | K2: DESIGN | L2: ASSEMBLY | M2: FORMATION | N2: SIZE - L | O2: TOP | P2: SCREEN | Q2: DESCRIPTION | R2: POPULAR | S2: 3D | T2: LIST PRICE | U2: NET : 10L = 10% OFF | V2: NET : 10-20L = 15% OFF | W2: NET : 20-40L = 20% OFF | X2: NET : >40L = 30% OFF
I3: WORKSTATIONS
B4: W | C4: FLX | D4: LNR | E4: SH | F4: PB | G4: 900 | H4: F | I4: =CONCATENATE(B4,C4,"-",D4,"-",E4,"-",F4,"-",G4,"-",H4) -> WFLX-LNR-SH-PB-900-F | J4: WORKSTATION | K4: ='MASTER DATA'!B33 -> FLEXI | L4: LINEAR | M4: SHARING | N4: 900 | O4: ='MASTER DATA'!B21 -> PLPB BSL | P4: ='MASTER DATA'!B52 -> FABRIC | Q4: {="Actual size: "&N4&" x 600mm per user"&CHAR(10)&CHAR(10)&"Formation - "&K4&" "&M4&CHAR(10)&CHAR(10)&"Top material: "&INDEX('MASTER DATA'!$D$21:$D$29,MATCH(O4,'MASTER DATA'!$B$21:$B$29,0))&CHAR(10)&"Color specs: TBD"&CHAR(10)&CHAR(10)&"Leg: "&INDEX('MASTER DATA'!$D$33:$D$37,MATCH(K4,'MASTER DATA'!$B$33:$B$37,0))&CHAR(10)&"Color specs: TBD"&CHAR(10)&CHAR(10)&"Electrification: "&'MASTER DATA'!D42&CHAR(10)&"Color specs: TBD"&CHAR(10)&CHAR(10)&"Screen: "&INDEX('MASTER DATA'!$D$52:$D$54,MATCH(P4,'MASTER DATA'!$B$52:$B$54,0))&CHAR(10)&"Color specs: TBD"} -> Actual size: 900 x 600mm per user Formation - FLEXI SHARING Top material: 18MM PRE-LAMINATED PARTICLE BOARD BOTH SIDES LAMINATE WITH EDGEBANDING Color specs: TBD Leg: MS+ALUMINUM LEG WITH POWDER COATING Color specs: TBD Electrification: 450MM XIO FLAP + SWITCH PLATE INSIDE, *switches not in Burosys scope Color specs: TBD Screen: L:6" LESS THAN TOP LENGTH, H400mm, D30mm FABRIC PINUP BOARD WITH ALUMINUM TRIMS Color specs: TBD | S4: RENDER 1 : FLEXI SHARING FABRIC | T4: =INDIRECT("'CALC FLX WST'!R"&(ROW()-3)*7) -> 11200 | U4: =T4*0.9 -> 10080 | V4: =T4*0.85 -> 9520 | W4: =T4*0.8 -> 8960 | X4: =T4*0.7 -> 7840
B5: W | C5: FLX | D5: LNR | E5: SH | F5: PB | G5: 900 | H5: G | I5: =CONCATENATE(B5,C5,"-",D5,"-",E5,"-",F5,"-",G5,"-",H5) -> WFLX-LNR-SH-PB-900-G | J5: WORKSTATION | K5: =K4 -> FLEXI | L5: LINEAR | M5: SHARING | N5: 900 | O5: =O4 -> PLPB BSL | P5: ='MASTER DATA'!B53 -> GLASS | Q5: {="Actual size: "&N5&" x 600mm per user"&CHAR(10)&CHAR(10)&"Formation - "&K5&" "&M5&CHAR(10)&CHAR(10)&"Top material: "&INDEX('MASTER DATA'!$D$21:$D$29,MATCH(O5,'MASTER DATA'!$B$21:$B$29,0))&CHAR(10)&"Color specs: TBD"&CHAR(10)&CHAR(10)&"Leg: "&INDEX('MASTER DATA'!$D$33:$D$37,MATCH(K5,'MASTER DATA'!$B$33:$B$37,0))&CHAR(10)&"Color specs: TBD"&CHAR(10)&CHAR(10)&"Electrification: "&'MASTER DATA'!D43&CHAR(10)&"Color specs: TBD"&CHAR(10)&CHAR(10)&"Screen: "&INDEX('MASTER DATA'!$D$52:$D$54,MATCH(P5,'MASTER DATA'!$B$52:$B$54,0))&CHAR(10)&"Color specs: TBD"} -> Actual size: 900 x 600mm per user Formation - FLEXI SHARING Top material: 18MM PRE-LAMINATED PARTICLE BOARD BOTH SIDES LAMINATE WITH EDGEBANDING Color specs: TBD Leg: MS+ALUMINUM LEG WITH POWDER COATING Color specs: TBD Electrification: Q CURVY POP BOX Color specs: TBD Screen: 4+4MM SANDWICHED BACK PAINTED MAGNETIC GLASS SCREEN Color specs: TBD | S5: RENDER 2 : FLEXI SHARING GLASS | T5: =INDIRECT("'CALC FLX WST'!R"&(ROW()-3)*7) -> 11400 | U5: =T5*0.9 -> 10260 | V5: =T5*0.85 -> 9690 | W5: =T5*0.8 -> 9120 | X5: =T5*0.7 -> 7980
B6: W | C6: FLX | D6: LNR | E6: SH | F6: PB | G6: 900 | H6: X | I6: =CONCATENATE(B6,C6,"-",D6,"-",E6,"-",F6,"-",G6,"-",H6) -> WFLX-LNR-SH-PB-900-X | J6: WORKSTATION | K6: FLEXI | L6: LINEAR | M6: SHARING | N6: 900 | O6: PLPB BSL | P6: ='MASTER DATA'!B54 -> NONE | Q6: {="Actual size: "&N6&" x 600mm per user"&CHAR(10)&CHAR(10)&"Formation - "&K6&" "&M6&CHAR(10)&CHAR(10)&"Top material: "&INDEX('MASTER DATA'!$D$21:$D$29,MATCH(O6,'MASTER DATA'!$B$21:$B$29,0))&CHAR(10)&"Color specs: TBD"&CHAR(10)&CHAR(10)&"Leg: "&INDEX('MASTER DATA'!$D$33:$D$37,MATCH(K6,'MASTER DATA'!$B$33:$B$37,0))&CHAR(10)&"Color specs: TBD"&CHAR(10)&CHAR(10)&"Electrification: "&'MASTER DATA'!D44&CHAR(10)&"Color specs: TBD"&CHAR(10)&CHAR(10)&"Screen: "&INDEX('MASTER DATA'!$D$52:$D$54,MATCH(P6,'MASTER DATA'!$B$52:$B$54,0))&CHAR(10)&"Color specs: TBD"} -> Actual size: 900 x 600mm per user Formation - FLEXI SHARING Top material: 18MM PRE-LAMINATED PARTICLE BOARD BOTH SIDES LAMINATE WITH EDGEBANDING Color specs: TBD Leg: MS+ALUMINUM LEG WITH POWDER COATING Color specs: TBD Electrification: 4+4 SWITCHES WITH SCREEN HOLDER Color specs: TBD Screen: Color specs: TBD | S6: RENDER 3 : FLEXI SHARING NO SCREEN | T6: =INDIRECT("'CALC FLX WST'!R"&(ROW()-3)*7) -> 9500 | U6: =T6*0.9 -> 8550 | V6: =T6*0.85 -> 8075 | W6: =T6*0.8 -> 7600 | X6: =T6*0.7 -> 6650
B7: W | C7: FLX | D7: LNR | E7: SH | F7: PLM | G7: 900 | H7: F | I7: =CONCATENATE(B7,C7,"-",D7,"-",E7,"-",F7,"-",G7,"-",H7) -> WFLX-LNR-SH-PLM-900-F | J7: WORKSTATION | K7: FLEXI | L7: LINEAR | M7: SHARING | N7: 900 | O7: PLMDF BSL | P7: =P4 -> FABRIC | Q7: {="Actual size: "&N7&" x 600mm per user"&CHAR(10)&CHAR(10)&"Formation - "&K7&" "&M7&CHAR(10)&CHAR(10)&"Top material: "&INDEX('MASTER DATA'!$D$21:$D$29,MATCH(O7,'MASTER DATA'!$B$21:$B$29,0))&CHAR(10)&"Color specs: TBD"&CHAR(10)&CHAR(10)&"Leg: "&INDEX('MASTER DATA'!$D$33:$D$37,MATCH(K7,'MASTER DATA'!$B$33:$B$37,0))&CHAR(10)&"Color specs: TBD"&CHAR(10)&CHAR(10)&"Electrification: "&'MASTER DATA'!D45&CHAR(10)&"Color specs: TBD"&CHAR(10)&CHAR(10)&"Screen: "&INDEX('MASTER DATA'!$D$52:$D$54,MATCH(P7,'MASTER DATA'!$B$52:$B$54,0))&CHAR(10)&"Color specs: TBD"} -> Actual size: 900 x 600mm per user Formation - FLEXI SHARING Top material: 18MM PRE-LAMINATED MDF(MEDIUM DESNSITY FIBER) BOARD BOTH SIDES LAMINATE Color specs: TBD Leg: MS+ALUMINUM LEG WITH POWDER COATING Color specs: TBD Electrification: 2 WAY ACCESS FLAP WITH SWITCH PLATE INSIDE Color specs: TBD Screen: L:6" LESS THAN TOP LENGTH, H400mm, D30mm FABRIC PINUP BOARD WITH ALUMINUM TRIMS Color specs: TBD | S7: RENDER 1 : FLEXI SHARING FABRIC | T7: =INDIRECT("'CALC FLX WST'!R"&(ROW()-3)*7) -> 12100 | U7: =T7*0.9 -> 10890 | V7: =T7*0.85 -> 10285 | W7: =T7*0.8 -> 9680 | X7: =T7*0.7 -> 8470
B8: W | C8: FLX | D8: LNR | E8: SH | F8: PLM | G8: 900 | H8: G | I8: =CONCATENATE(B8,C8,"-",D8,"-",E8,"-",F8,"-",G8,"-",H8) -> WFLX-LNR-SH-PLM-900-G | J8: WORKSTATION | K8: FLEXI | L8: LINEAR | M8: SHARING | N8: 900 | O8: PLMDF BSL | P8: =P5 -> GLASS | Q8: {="Actual size: "&N8&" x 600mm per user"&CHAR(10)&CHAR(10)&"Formation - "&K8&" "&M8&CHAR(10)&CHAR(10)&"Top material: "&INDEX('MASTER DATA'!$D$21:$D$29,MATCH(O8,'MASTER DATA'!$B$21:$B$29,0))&CHAR(10)&"Color specs: TBD"&CHAR(10)&CHAR(10)&"Leg: "&INDEX('MASTER DATA'!$D$33:$D$37,MATCH(K8,'MASTER DATA'!$B$33:$B$37,0))&CHAR(10)&"Color specs: TBD"&CHAR(10)&CHAR(10)&"Electrification: "&'MASTER DATA'!D46&CHAR(10)&"Color specs: TBD"&CHAR(10)&CHAR(10)&"Screen: "&INDEX('MASTER DATA'!$D$52:$D$54,MATCH(P8,'MASTER DATA'!$B$52:$B$54,0))&CHAR(10)&"Color specs: TBD"} -> Actual size: 900 x 600mm per user Formation - FLEXI SHARING Top material: 18MM PRE-LAMINATED MDF(MEDIUM DESNSITY FIBER) BOARD BOTH SIDES LAMINATE Color specs: TBD Leg: MS+ALUMINUM LEG WITH POWDER COATING Color specs: TBD Electrification: 100MM VERTICAL BOX Color specs: TBD Screen: 4+4MM SANDWICHED BACK PAINTED MAGNETIC GLASS SCREEN Color specs: TBD | S8: RENDER 2 : FLEXI SHARING GLASS | T8: =INDIRECT("'CALC FLX WST'!R"&(ROW()-3)*7) -> 12300 | U8: =T8*0.9 -> 11070 | V8: =T8*0.85 -> 10455 | W8: =T8*0.8 -> 9840 | X8: =T8*0.7 -> 8610
B9: W | C9: FLX | D9: LNR | E9: SH | F9: PLM | G9: 900 | H9: X | I9: =CONCATENATE(B9,C9,"-",D9,"-",E9,"-",F9,"-",G9,"-",H9) -> WFLX-LNR-SH-PLM-900-X | J9: WORKSTATION | K9: FLEXI | L9: LINEAR | M9: SHARING | N9: 900 | O9: PLMDF BSL | P9: =P6 -> NONE | Q9: {="Actual size: "&N9&" x 600mm per user"&CHAR(10)&CHAR(10)&"Formation - "&K9&" "&M9&CHAR(10)&CHAR(10)&"Top material: "&INDEX('MASTER DATA'!$D$21:$D$29,MATCH(O9,'MASTER DATA'!$B$21:$B$29,0))&CHAR(10)&"Color specs: TBD"&CHAR(10)&CHAR(10)&"Leg: "&INDEX('MASTER DATA'!$D$33:$D$37,MATCH(K9,'MASTER DATA'!$B$33:$B$37,0))&CHAR(10)&"Color specs: TBD"&CHAR(10)&CHAR(10)&"Electrification: "&'MASTER DATA'!D47&CHAR(10)&"Color specs: TBD"&CHAR(10)&CHAR(10)&"Screen: "&INDEX('MASTER DATA'!$D$52:$D$54,MATCH(P9,'MASTER DATA'!$B$52:$B$54,0))&CHAR(10)&"Color specs: TBD"} -> Actual size: 900 x 600mm per user Formation - FLEXI SHARING Top material: 18MM PRE-LAMINATED MDF(MEDIUM DESNSITY FIBER) BOARD BOTH SIDES LAMINATE Color specs: TBD Leg: MS+ALUMINUM LEG WITH POWDER COATING Color specs: TBD Electrification: 450MM VERTICAL BOX Color specs: TBD Screen: Color specs: TBD | S9: RENDER 3 : FLEXI SHARING NO SCREEN | T9: =INDIRECT("'CALC FLX WST'!R"&(ROW()-3)*7) -> 10300 | U9: =T9*0.9 -> 9270 | V9: =T9*0.85 -> 8755 | W9: =T9*0.8 -> 8240 | X9: =T9*0.7 -> 7210
B10: W | C10: FLX | D10: LNR | E10: SH | F10: PoLM | G10: 900 | H10: F | I10: =CONCATENATE(B10,C10,"-",D10,"-",E10,"-",F10,"-",G10,"-",H10) -> WFLX-LNR-SH-PoLM-900-F | J10: WORKSTATION | K10: FLEXI | L10: LINEAR | M10: SHARING | N10: 900 | O10: PoLMDF | P10: FABRIC | Q10: {="Actual size: "&N10&" x 600mm per user"&CHAR(10)&CHAR(10)&"Formation - "&K10&" "&M10&CHAR(10)&CHAR(10)&"Top material: "&INDEX('MASTER DATA'!$D$21:$D$29,MATCH(O10,'MASTER DATA'!$B$21:$B$29,0))&CHAR(10)&"Color specs: TBD"&CHAR(10)&CHAR(10)&"Leg: "&INDEX('MASTER DATA'!$D$33:$D$37,MATCH(K10,'MASTER DATA'!$B$33:$B$37,0))&CHAR(10)&"Color specs: TBD"&CHAR(10)&CHAR(10)&"Electrification: "&'MASTER DATA'!D48&CHAR(10)&"Color specs: TBD"&CHAR(10)&CHAR(10)&"Screen: "&INDEX('MASTER DATA'!$D$52:$D$54,MATCH(P10,'MASTER DATA'!$B$52:$B$54,0))&CHAR(10)&"Color specs: TBD"} -> Actual size: 900 x 600mm per user Formation - FLEXI SHARING Top material: 18MM POST-LAMINATED MDF(MEDIUM DESNSITY FIBER) BOARD BOTH SIDES LAMINATE Color specs: TBD Leg: MS+ALUMINUM LEG WITH POWDER COATING Color specs: TBD Electrification: VERTEBRA SNAKE Color specs: TBD Screen: L:6" LESS THAN TOP LENGTH, H400mm, D30mm FABRIC PINUP BOARD WITH ALUMINUM TRIMS Color specs: TBD | S10: RENDER 1 : FLEXI SHARING FABRIC | T10: =INDIRECT("'CALC FLX WST'!R"&(ROW()-3)*7) -> 16900 | U10: =T10*0.9 -> 15210 | V10: =T10*0.85 -> 14365 | W10: =T10*0.8 -> 13520 | X10: =T10*0.7 -> 11830
B11: W | C11: FLX | D11: LNR | E11: SH | F11: PoLM | G11: 900 | H11: G | I11: =CONCATENATE(B11,C11,"-",D11,"-",E11,"-",F11,"-",G11,"-",H11) -> WFLX-LNR-SH-PoLM-900-G | J11: WORKSTATION | K11: FLEXI | L11: LINEAR | M11: SHARING | N11: 900 | O11: PoLMDF | P11: GLASS | Q11: {="Actual size: "&N11&" x 600mm per user"&CHAR(10)&CHAR(10)&"Formation - "&K11&" "&M11&CHAR(10)&CHAR(10)&"Top material: "&INDEX('MASTER DATA'!$D$21:$D$29,MATCH(O11,'MASTER DATA'!$B$21:$B$29,0))&CHAR(10)&"Color specs: TBD"&CHAR(10)&CHAR(10)&"Leg: "&INDEX('MASTER DATA'!$D$33:$D$37,MATCH(K11,'MASTER DATA'!$B$33:$B$37,0))&CHAR(10)&"Color specs: TBD"&CHAR(10)&CHAR(10)&"Electrification: "&'MASTER DATA'!D49&CHAR(10)&"Color specs: TBD"&CHAR(10)&CHAR(10)&"Screen: "&INDEX('MASTER DATA'!$D$52:$D$54,MATCH(P11,'MASTER DATA'!$B$52:$B$54,0))&CHAR(10)&"Color specs: TBD"} -> Actual size: 900 x 600mm per user Formation - FLEXI SHARING Top material: 18MM POST-LAMINATED MDF(MEDIUM DESNSITY FIBER) BOARD BOTH SIDES LAMINATE Color specs: TBD Leg: MS+ALUMINUM LEG WITH POWDER COATING Color specs: TBD Electrification: Color specs: TBD Screen: 4+4MM SANDWICHED BACK PAINTED MAGNETIC GLASS SCREEN Color specs: TBD | S11: RENDER 2 : FLEXI SHARING GLASS | T11: =INDIRECT("'CALC FLX WST'!R"&(ROW()-3)*7) -> 17200 | U11: =T11*0.9 -> 15480 | V11: =T11*0.85 -> 14620 | W11: =T11*0.8 -> 13760 | X11: =T11*0.7 -> 12040
B12: W | C12: FLX | D12: LNR | E12: SH | F12: PoLM | G12: 900 | H12: X | I12: =CONCATENATE(B12,C12,"-",D12,"-",E12,"-",F12,"-",G12,"-",H12) -> WFLX-LNR-SH-PoLM-900-X | J12: WORKSTATION | K12: FLEXI | L12: LINEAR | M12: SHARING | N12: 900 | O12: PoLMDF | P12: NONE | Q12: {="Actual size: "&N12&" x 600mm per user"&CHAR(10)&CHAR(10)&"Formation - "&K12&" "&M12&CHAR(10)&CHAR(10)&"Top material: "&INDEX('MASTER DATA'!$D$21:$D$29,MATCH(O12,'MASTER DATA'!$B$21:$B$29,0))&CHAR(10)&"Color specs: TBD"&CHAR(10)&CHAR(10)&"Leg: "&INDEX('MASTER DATA'!$D$33:$D$37,MATCH(K12,'MASTER DATA'!$B$33:$B$37,0))&CHAR(10)&"Color specs: TBD"&CHAR(10)&CHAR(10)&"Electrification: "&'MASTER DATA'!D50&CHAR(10)&"Color specs: TBD"&CHAR(10)&CHAR(10)&"Screen: "&INDEX('MASTER DATA'!$D$52:$D$54,MATCH(P12,'MASTER DATA'!$B$52:$B$54,0))&CHAR(10)&"Color specs: TBD"} -> Actual size: 900 x 600mm per user Formation - FLEXI SHARING Top material: 18MM POST-LAMINATED MDF(MEDIUM DESNSITY FIBER) BOARD BOTH SIDES LAMINATE Color specs: TBD Leg: MS+ALUMINUM LEG WITH POWDER COATING Color specs: TBD Electrification: Color specs: TBD Screen: Color specs: TBD | S12: RENDER 3 : FLEXI SHARING NO SCREEN | T12: =INDIRECT("'CALC FLX WST'!R"&(ROW()-3)*7) -> 15200 | U12: =T12*0.9 -> 13680 | V12: =T12*0.85 -> 12920 | W12: =T12*0.8 -> 12160 | X12: =T12*0.7 -> 10640
B13: W | C13: FLX | D13: LNR | E13: SH | F13: LVM | G13: 900 | H13: F | I13: =CONCATENATE(B13,C13,"-",D13,"-",E13,"-",F13,"-",G13,"-",H13) -> WFLX-LNR-SH-LVM-900-F | J13: WORKSTATION | K13: FLEXI | L13: LINEAR | M13: SHARING | N13: 900 | O13: LUVIH-MDF | P13: FABRIC | Q13: {="Actual size: "&N13&" x 600mm per user"&CHAR(10)&CHAR(10)&"Formation - "&K13&" "&M13&CHAR(10)&CHAR(10)&"Top material: "&INDEX('MASTER DATA'!$D$21:$D$29,MATCH(O13,'MASTER DATA'!$B$21:$B$29,0))&CHAR(10)&"Color specs: TBD"&CHAR(10)&CHAR(10)&"Leg: "&INDEX('MASTER DATA'!$D$33:$D$37,MATCH(K13,'MASTER DATA'!$B$33:$B$37,0))&CHAR(10)&"Color specs: TBD"&CHAR(10)&CHAR(10)&"Electrification: "&'MASTER DATA'!D51&CHAR(10)&"Color specs: TBD"&CHAR(10)&CHAR(10)&"Screen: "&INDEX('MASTER DATA'!$D$52:$D$54,MATCH(P13,'MASTER DATA'!$B$52:$B$54,0))&CHAR(10)&"Color specs: TBD"} -> #N/A | S13: RENDER 1 : FLEXI SHARING FABRIC | T13: =INDIRECT("'CALC FLX WST'!R"&(ROW()-3)*7) -> 19100 | U13: =T13*0.9 -> 17190 | V13: =T13*0.85 -> 16235 | W13: =T13*0.8 -> 15280 | X13: =T13*0.7 -> 13370
B14: W | C14: FLX | D14: LNR | E14: SH | F14: LVM | G14: 900 | H14: G | I14: =CONCATENATE(B14,C14,"-",D14,"-",E14,"-",F14,"-",G14,"-",H14) -> WFLX-LNR-SH-LVM-900-G | J14: WORKSTATION | K14: FLEXI | L14: LINEAR | M14: SHARING | N14: 900 | O14: LUVIH-MDF | P14: GLASS | Q14: {="Actual size: "&N14&" x 600mm per user"&CHAR(10)&CHAR(10)&"Formation - "&K14&" "&M14&CHAR(10)&CHAR(10)&"Top material: "&INDEX('MASTER DATA'!$D$21:$D$29,MATCH(O14,'MASTER DATA'!$B$21:$B$29,0))&CHAR(10)&"Color specs: TBD"&CHAR(10)&CHAR(10)&"Leg: "&INDEX('MASTER DATA'!$D$33:$D$37,MATCH(K14,'MASTER DATA'!$B$33:$B$37,0))&CHAR(10)&"Color specs: TBD"&CHAR(10)&CHAR(10)&"Electrification: "&'MASTER DATA'!D52&CHAR(10)&"Color specs: TBD"&CHAR(10)&CHAR(10)&"Screen: "&INDEX('MASTER DATA'!$D$52:$D$54,MATCH(P14,'MASTER DATA'!$B$52:$B$54,0))&CHAR(10)&"Color specs: TBD"} -> #N/A | S14: RENDER 2 : FLEXI SHARING GLASS | T14: =INDIRECT("'CALC FLX WST'!R"&(ROW()-3)*7) -> 19300 | U14: =T14*0.9 -> 17370 | V14: =T14*0.85 -> 16405 | W14: =T14*0.8 -> 15440 | X14: =T14*0.7 -> 13510
B15: W | C15: FLX | D15: LNR | E15: SH | F15: LVM | G15: 900 | H15: X | I15: =CONCATENATE(B15,C15,"-",D15,"-",E15,"-",F15,"-",G15,"-",H15) -> WFLX-LNR-SH-LVM-900-X | J15: WORKSTATION | K15: FLEXI | L15: LINEAR | M15: SHARING | N15: 900 | O15: LUVIH-MDF | P15: NONE | Q15: {="Actual size: "&N15&" x 600mm per user"&CHAR(10)&CHAR(10)&"Formation - "&K15&" "&M15&CHAR(10)&CHAR(10)&"Top material: "&INDEX('MASTER DATA'!$D$21:$D$29,MATCH(O15,'MASTER DATA'!$B$21:$B$29,0))&CHAR(10)&"Color specs: TBD"&CHAR(10)&CHAR(10)&"Leg: "&INDEX('MASTER DATA'!$D$33:$D$37,MATCH(K15,'MASTER DATA'!$B$33:$B$37,0))&CHAR(10)&"Color specs: TBD"&CHAR(10)&CHAR(10)&"Electrification: "&'MASTER DATA'!D53&CHAR(10)&"Color specs: TBD"&CHAR(10)&CHAR(10)&"Screen: "&INDEX('MASTER DATA'!$D$52:$D$54,MATCH(P15,'MASTER DATA'!$B$52:$B$54,0))&CHAR(10)&"Color specs: TBD"} -> #N/A | S15: RENDER 3 : FLEXI SHARING NO SCREEN | T15: =INDIRECT("'CALC FLX WST'!R"&(ROW()-3)*7) -> 17300 | U15: =T15*0.9 -> 15570 | V15: =T15*0.85 -> 14705 | W15: =T15*0.8 -> 13840 | X15: =T15*0.7 -> 12110
B16: W | C16: FLX | D16: LNR | E16: SH | F16: LVP | G16: 900 | H16: F | I16: =CONCATENATE(B16,C16,"-",D16,"-",E16,"-",F16,"-",G16,"-",H16) -> WFLX-LNR-SH-LVP-900-F | J16: WORKSTATION | K16: FLEXI | L16: LINEAR | M16: SHARING | N16: 900 | O16: LUVIH-PLY | P16: FABRIC | Q16: {="Actual size: "&N16&" x 600mm per user"&CHAR(10)&CHAR(10)&"Formation - "&K16&" "&M16&CHAR(10)&CHAR(10)&"Top material: "&INDEX('MASTER DATA'!$D$21:$D$29,MATCH(O16,'MASTER DATA'!$B$21:$B$29,0))&CHAR(10)&"Color specs: TBD"&CHAR(10)&CHAR(10)&"Leg: "&INDEX('MASTER DATA'!$D$33:$D$37,MATCH(K16,'MASTER DATA'!$B$33:$B$37,0))&CHAR(10)&"Color specs: TBD"&CHAR(10)&CHAR(10)&"Electrification: "&'MASTER DATA'!D54&CHAR(10)&"Color specs: TBD"&CHAR(10)&CHAR(10)&"Screen: "&INDEX('MASTER DATA'!$D$52:$D$54,MATCH(P16,'MASTER DATA'!$B$52:$B$54,0))&CHAR(10)&"Color specs: TBD"} -> #N/A | S16: RENDER 1 : FLEXI SHARING FABRIC | T16: =INDIRECT("'CALC FLX WST'!R"&(ROW()-3)*7) -> 20200 | U16: =T16*0.9 -> 18180 | V16: =T16*0.85 -> 17170 | W16: =T16*0.8 -> 16160 | X16: =T16*0.7 -> 14140
B17: W | C17: FLX | D17: LNR | E17: SH | F17: LVP | G17: 900 | H17: G | I17: =CONCATENATE(B17,C17,"-",D17,"-",E17,"-",F17,"-",G17,"-",H17) -> WFLX-LNR-SH-LVP-900-G | J17: WORKSTATION | K17: FLEXI | L17: LINEAR | M17: SHARING | N17: 900 | O17: LUVIH-PLY | P17: GLASS | Q17: {="Actual size: "&N17&" x 600mm per user"&CHAR(10)&CHAR(10)&"Formation - "&K17&" "&M17&CHAR(10)&CHAR(10)&"Top material: "&INDEX('MASTER DATA'!$D$21:$D$29,MATCH(O17,'MASTER DATA'!$B$21:$B$29,0))&CHAR(10)&"Color specs: TBD"&CHAR(10)&CHAR(10)&"Leg: "&INDEX('MASTER DATA'!$D$33:$D$37,MATCH(K17,'MASTER DATA'!$B$33:$B$37,0))&CHAR(10)&"Color specs: TBD"&CHAR(10)&CHAR(10)&"Electrification: "&'MASTER DATA'!D55&CHAR(10)&"Color specs: TBD"&CHAR(10)&CHAR(10)&"Screen: "&INDEX('MASTER DATA'!$D$52:$D$54,MATCH(P17,'MASTER DATA'!$B$52:$B$54,0))&CHAR(10)&"Color specs: TBD"} -> #N/A | S17: RENDER 2 : FLEXI SHARING GLASS | T17: =INDIRECT("'CALC FLX WST'!R"&(ROW()-3)*7) -> 20400 | U17: =T17*0.9 -> 18360 | V17: =T17*0.85 -> 17340 | W17: =T17*0.8 -> 16320 | X17: =T17*0.7 -> 14280
B18: W | C18: FLX | D18: LNR | E18: SH | F18: LVP | G18: 900 | H18: X | I18: =CONCATENATE(B18,C18,"-",D18,"-",E18,"-",F18,"-",G18,"-",H18) -> WFLX-LNR-SH-LVP-900-X | J18: WORKSTATION | K18: FLEXI | L18: LINEAR | M18: SHARING | N18: 900 | O18: LUVIH-PLY | P18: NONE | Q18: {="Actual size: "&N18&" x 600mm per user"&CHAR(10)&CHAR(10)&"Formation - "&K18&" "&M18&CHAR(10)&CHAR(10)&"Top material: "&INDEX('MASTER DATA'!$D$21:$D$29,MATCH(O18,'MASTER DATA'!$B$21:$B$29,0))&CHAR(10)&"Color specs: TBD"&CHAR(10)&CHAR(10)&"Leg: "&INDEX('MASTER DATA'!$D$33:$D$37,MATCH(K18,'MASTER DATA'!$B$33:$B$37,0))&CHAR(10)&"Color specs: TBD"&CHAR(10)&CHAR(10)&"Electrification: "&'MASTER DATA'!D56&CHAR(10)&"Color specs: TBD"&CHAR(10)&CHAR(10)&"Screen: "&INDEX('MASTER DATA'!$D$52:$D$54,MATCH(P18,'MASTER DATA'!$B$52:$B$54,0))&CHAR(10)&"Color specs: TBD"} -> #N/A | S18: RENDER 3 : FLEXI SHARING NO SCREEN | T18: =INDIRECT("'CALC FLX WST'!R"&(ROW()-3)*7) -> 18400 | U18: =T18*0.9 -> 16560 | V18: =T18*0.85 -> 15640 | W18: =T18*0.8 -> 14720 | X18: =T18*0.7 -> 12880
B19: W | C19: FLX | D19: LNR | E19: SH | F19: MB | G19: 900 | H19: F | I19: =CONCATENATE(B19,C19,"-",D19,"-",E19,"-",F19,"-",G19,"-",H19) -> WFLX-LNR-SH-MB-900-F | J19: WORKSTATION | K19: FLEXI | L19: LINEAR | M19: SHARING | N19: 900 | O19: MEMBRANE | P19: FABRIC | Q19: {="Actual size: "&N19&" x 600mm per user"&CHAR(10)&CHAR(10)&"Formation - "&K19&" "&M19&CHAR(10)&CHAR(10)&"Top material: "&INDEX('MASTER DATA'!$D$21:$D$29,MATCH(O19,'MASTER DATA'!$B$21:$B$29,0))&CHAR(10)&"Color specs: TBD"&CHAR(10)&CHAR(10)&"Leg: "&INDEX('MASTER DATA'!$D$33:$D$37,MATCH(K19,'MASTER DATA'!$B$33:$B$37,0))&CHAR(10)&"Color specs: TBD"&CHAR(10)&CHAR(10)&"Electrification: "&'MASTER DATA'!D57&CHAR(10)&"Color specs: TBD"&CHAR(10)&CHAR(10)&"Screen: "&INDEX('MASTER DATA'!$D$52:$D$54,MATCH(P19,'MASTER DATA'!$B$52:$B$54,0))&CHAR(10)&"Color specs: TBD"} -> Actual size: 900 x 600mm per user Formation - FLEXI SHARING Top material: 25MM GERMAN MEMBRANE ON POST-LAMINATED MDF(MEDIUM DESNSITY FIBER) BOARD Color specs: TBD Leg: MS+ALUMINUM LEG WITH POWDER COATING Color specs: TBD Electrification: FULL NAME Color specs: TBD Screen: L:6" LESS THAN TOP LENGTH, H400mm, D30mm FABRIC PINUP BOARD WITH ALUMINUM TRIMS Color specs: TBD | S19: RENDER 1 : FLEXI SHARING FABRIC | T19: =INDIRECT("'CALC FLX WST'!R"&(ROW()-3)*7) -> 26400 | U19: =T19*0.9 -> 23760 | V19: =T19*0.85 -> 22440 | W19: =T19*0.8 -> 21120 | X19: =T19*0.7 -> 18480
B20: W | C20: FLX | D20: LNR | E20: SH | F20: MB | G20: 900 | H20: G | I20: =CONCATENATE(B20,C20,"-",D20,"-",E20,"-",F20,"-",G20,"-",H20) -> WFLX-LNR-SH-MB-900-G | J20: WORKSTATION | K20: FLEXI | L20: LINEAR | M20: SHARING | N20: 900 | O20: MEMBRANE | P20: GLASS | Q20: {="Actual size: "&N20&" x 600mm per user"&CHAR(10)&CHAR(10)&"Formation - "&K20&" "&M20&CHAR(10)&CHAR(10)&"Top material: "&INDEX('MASTER DATA'!$D$21:$D$29,MATCH(O20,'MASTER DATA'!$B$21:$B$29,0))&CHAR(10)&"Color specs: TBD"&CHAR(10)&CHAR(10)&"Leg: "&INDEX('MASTER DATA'!$D$33:$D$37,MATCH(K20,'MASTER DATA'!$B$33:$B$37,0))&CHAR(10)&"Color specs: TBD"&CHAR(10)&CHAR(10)&"Electrification: "&'MASTER DATA'!D58&CHAR(10)&"Color specs: TBD"&CHAR(10)&CHAR(10)&"Screen: "&INDEX('MASTER DATA'!$D$52:$D$54,MATCH(P20,'MASTER DATA'!$B$52:$B$54,0))&CHAR(10)&"Color specs: TBD"} -> Actual size: 900 x 600mm per user Formation - FLEXI SHARING Top material: 25MM GERMAN MEMBRANE ON POST-LAMINATED MDF(MEDIUM DESNSITY FIBER) BOARD Color specs: TBD Leg: MS+ALUMINUM LEG WITH POWDER COATING Color specs: TBD Electrification: PLPB/PLMDF SIDE UNIT WITH STANDARD LOCK Color specs: TBD Screen: 4+4MM SANDWICHED BACK PAINTED MAGNETIC GLASS SCREEN Color specs: TBD | S20: RENDER 2 : FLEXI SHARING GLASS | T20: =INDIRECT("'CALC FLX WST'!R"&(ROW()-3)*7) -> 26600 | U20: =T20*0.9 -> 23940 | V20: =T20*0.85 -> 22610 | W20: =T20*0.8 -> 21280 | X20: =T20*0.7 -> 18620
B21: W | C21: FLX | D21: LNR | E21: SH | F21: MB | G21: 900 | H21: X | I21: =CONCATENATE(B21,C21,"-",D21,"-",E21,"-",F21,"-",G21,"-",H21) -> WFLX-LNR-SH-MB-900-X | J21: WORKSTATION | K21: FLEXI | L21: LINEAR | M21: SHARING | N21: 900 | O21: MEMBRANE | P21: NONE | Q21: {="Actual size: "&N21&" x 600mm per user"&CHAR(10)&CHAR(10)&"Formation - "&K21&" "&M21&CHAR(10)&CHAR(10)&"Top material: "&INDEX('MASTER DATA'!$D$21:$D$29,MATCH(O21,'MASTER DATA'!$B$21:$B$29,0))&CHAR(10)&"Color specs: TBD"&CHAR(10)&CHAR(10)&"Leg: "&INDEX('MASTER DATA'!$D$33:$D$37,MATCH(K21,'MASTER DATA'!$B$33:$B$37,0))&CHAR(10)&"Color specs: TBD"&CHAR(10)&CHAR(10)&"Electrification: "&'MASTER DATA'!D59&CHAR(10)&"Color specs: TBD"&CHAR(10)&CHAR(10)&"Screen: "&INDEX('MASTER DATA'!$D$52:$D$54,MATCH(P21,'MASTER DATA'!$B$52:$B$54,0))&CHAR(10)&"Color specs: TBD"} -> Actual size: 900 x 600mm per user Formation - FLEXI SHARING Top material: 25MM GERMAN MEMBRANE ON POST-LAMINATED MDF(MEDIUM DESNSITY FIBER) BOARD Color specs: TBD Leg: MS+ALUMINUM LEG WITH POWDER COATING Color specs: TBD Electrification: LUVIH FACIA UNITS WITH DIGILOCK Color specs: TBD Screen: Color specs: TBD | S21: RENDER 3 : FLEXI SHARING NO SCREEN | T21: =INDIRECT("'CALC FLX WST'!R"&(ROW()-3)*7) -> 24600 | U21: =T21*0.9 -> 22140 | V21: =T21*0.85 -> 20910 | W21: =T21*0.8 -> 19680 | X21: =T21*0.7 -> 17220
B22: W | C22: FLX | D22: LNR | E22: SH | F22: PB | G22: 1200 | H22: F | I22: =CONCATENATE(B22,C22,"-",D22,"-",E22,"-",F22,"-",G22,"-",H22) -> WFLX-LNR-SH-PB-1200-F | J22: WORKSTATION | K22: FLEXI | L22: LINEAR | M22: SHARING | N22: 1200 | O22: PLPB BSL | P22: FABRIC | Q22: {="Actual size: "&N22&" x 600mm per user"&CHAR(10)&CHAR(10)&"Formation - "&K22&" "&M22&CHAR(10)&CHAR(10)&"Top material: "&INDEX('MASTER DATA'!$D$21:$D$29,MATCH(O22,'MASTER DATA'!$B$21:$B$29,0))&CHAR(10)&"Color specs: TBD"&CHAR(10)&CHAR(10)&"Leg: "&INDEX('MASTER DATA'!$D$33:$D$37,MATCH(K22,'MASTER DATA'!$B$33:$B$37,0))&CHAR(10)&"Color specs: TBD"&CHAR(10)&CHAR(10)&"Electrification: "&'MASTER DATA'!D60&CHAR(10)&"Color specs: TBD"&CHAR(10)&CHAR(10)&"Screen: "&INDEX('MASTER DATA'!$D$52:$D$54,MATCH(P22,'MASTER DATA'!$B$52:$B$54,0))&CHAR(10)&"Color specs: TBD"} -> Actual size: 1200 x 600mm per user Formation - FLEXI SHARING Top material: 18MM PRE-LAMINATED PARTICLE BOARD BOTH SIDES LAMINATE WITH EDGEBANDING Color specs: TBD Leg: MS+ALUMINUM LEG WITH POWDER COATING Color specs: TBD Electrification: Color specs: TBD Screen: L:6" LESS THAN TOP LENGTH, H400mm, D30mm FABRIC PINUP BOARD WITH ALUMINUM TRIMS Color specs: TBD | S22: RENDER 1 : FLEXI SHARING FABRIC | T22: =INDIRECT("'CALC FLX WST'!R"&(ROW()-3)*7) -> 13000 | U22: =T22*0.9 -> 11700 | V22: =T22*0.85 -> 11050 | W22: =T22*0.8 -> 10400 | X22: =T22*0.7 -> 9100
B23: W | C23: FLX | D23: LNR | E23: SH | F23: PB | G23: 1200 | H23: G | I23: =CONCATENATE(B23,C23,"-",D23,"-",E23,"-",F23,"-",G23,"-",H23) -> WFLX-LNR-SH-PB-1200-G | J23: WORKSTATION | K23: FLEXI | L23: LINEAR | M23: SHARING | N23: 1200 | O23: PLPB BSL | P23: GLASS | Q23: {="Actual size: "&N23&" x 600mm per user"&CHAR(10)&CHAR(10)&"Formation - "&K23&" "&M23&CHAR(10)&CHAR(10)&"Top material: "&INDEX('MASTER DATA'!$D$21:$D$29,MATCH(O23,'MASTER DATA'!$B$21:$B$29,0))&CHAR(10)&"Color specs: TBD"&CHAR(10)&CHAR(10)&"Leg: "&INDEX('MASTER DATA'!$D$33:$D$37,MATCH(K23,'MASTER DATA'!$B$33:$B$37,0))&CHAR(10)&"Color specs: TBD"&CHAR(10)&CHAR(10)&"Electrification: "&'MASTER DATA'!D61&CHAR(10)&"Color specs: TBD"&CHAR(10)&CHAR(10)&"Screen: "&INDEX('MASTER DATA'!$D$52:$D$54,MATCH(P23,'MASTER DATA'!$B$52:$B$54,0))&CHAR(10)&"Color specs: TBD"} -> Actual size: 1200 x 600mm per user Formation - FLEXI SHARING Top material: 18MM PRE-LAMINATED PARTICLE BOARD BOTH SIDES LAMINATE WITH EDGEBANDING Color specs: TBD Leg: MS+ALUMINUM LEG WITH POWDER COATING Color specs: TBD Electrification: Color specs: TBD Screen: 4+4MM SANDWICHED BACK PAINTED MAGNETIC GLASS SCREEN Color specs: TBD | R23: STD1 | S23: RENDER 2 : FLEXI SHARING GLASS | T23: =INDIRECT("'CALC FLX WST'!R"&(ROW()-3)*7) -> 13300 | U23: =T23*0.9 -> 11970 | V23: =T23*0.85 -> 11305 | W23: =T23*0.8 -> 10640 | X23: =T23*0.7 -> 9310
B24: W | C24: FLX | D24: LNR | E24: SH | F24: PB | G24: 1200 | H24: X | I24: =CONCATENATE(B24,C24,"-",D24,"-",E24,"-",F24,"-",G24,"-",H24) -> WFLX-LNR-SH-PB-1200-X | J24: WORKSTATION | K24: FLEXI | L24: LINEAR | M24: SHARING | N24: 1200 | O24: PLPB BSL | P24: NONE | Q24: {="Actual size: "&N24&" x 600mm per user"&CHAR(10)&CHAR(10)&"Formation - "&K24&" "&M24&CHAR(10)&CHAR(10)&"Top material: "&INDEX('MASTER DATA'!$D$21:$D$29,MATCH(O24,'MASTER DATA'!$B$21:$B$29,0))&CHAR(10)&"Color specs: TBD"&CHAR(10)&CHAR(10)&"Leg: "&INDEX('MASTER DATA'!$D$33:$D$37,MATCH(K24,'MASTER DATA'!$B$33:$B$37,0))&CHAR(10)&"Color specs: TBD"&CHAR(10)&CHAR(10)&"Electrification: "&'MASTER DATA'!D62&CHAR(10)&"Color specs: TBD"&CHAR(10)&CHAR(10)&"Screen: "&INDEX('MASTER DATA'!$D$52:$D$54,MATCH(P24,'MASTER DATA'!$B$52:$B$54,0))&CHAR(10)&"Color specs: TBD"} -> Actual size: 1200 x 600mm per user Formation - FLEXI SHARING Top material: 18MM PRE-LAMINATED PARTICLE BOARD BOTH SIDES LAMINATE WITH EDGEBANDING Color specs: TBD Leg: MS+ALUMINUM LEG WITH POWDER COATING Color specs: TBD Electrification: Color specs: TBD Screen: Color specs: TBD | S24: RENDER 3 : FLEXI SHARING NO SCREEN | T24: =INDIRECT("'CALC FLX WST'!R"&(ROW()-3)*7) -> 10700 | U24: =T24*0.9 -> 9630 | V24: =T24*0.85 -> 9095 | W24: =T24*0.8 -> 8560 | X24: =T24*0.7 -> 7490
B25: W | C25: FLX | D25: LNR | E25: SH | F25: PLM | G25: 1200 | H25: F | I25: =CONCATENATE(B25,C25,"-",D25,"-",E25,"-",F25,"-",G25,"-",H25) -> WFLX-LNR-SH-PLM-1200-F | J25: WORKSTATION | K25: FLEXI | L25: LINEAR | M25: SHARING | N25: 1200 | O25: PLMDF BSL | P25: FABRIC | S25: RENDER 1 : FLEXI SHARING FABRIC | T25: =INDIRECT("'CALC FLX WST'!R"&(ROW()-3)*7) -> 14100 | U25: =T25*0.9 -> 12690 | V25: =T25*0.85 -> 11985 | W25: =T25*0.8 -> 11280 | X25: =T25*0.7 -> 9870
B26: W | C26: FLX | D26: LNR | E26: SH | F26: PLM | G26: 1200 | H26: G | I26: =CONCATENATE(B26,C26,"-",D26,"-",E26,"-",F26,"-",G26,"-",H26) -> WFLX-LNR-SH-PLM-1200-G | J26: WORKSTATION | K26: FLEXI | L26: LINEAR | M26: SHARING | N26: 1200 | O26: PLMDF BSL | P26: GLASS | Q26: {="Actual size: "&N26&" x 600mm per user"&CHAR(10)&CHAR(10)&"Formation - "&K26&" "&M26&CHAR(10)&CHAR(10)&"Top material: "&INDEX('MASTER DATA'!$D$21:$D$29,MATCH(O26,'MASTER DATA'!$B$21:$B$29,0))&CHAR(10)&"Color specs: TBD"&CHAR(10)&CHAR(10)&"Leg: "&INDEX('MASTER DATA'!$D$33:$D$37,MATCH(K26,'MASTER DATA'!$B$33:$B$37,0))&CHAR(10)&"Color specs: TBD"&CHAR(10)&CHAR(10)&"Electrification: "&'MASTER DATA'!D64&CHAR(10)&"Color specs: TBD"&CHAR(10)&CHAR(10)&"Screen: "&INDEX('MASTER DATA'!$D$52:$D$54,MATCH(P26,'MASTER DATA'!$B$52:$B$54,0))&CHAR(10)&"Color specs: TBD"} -> Actual size: 1200 x 600mm per user Formation - FLEXI SHARING Top material: 18MM PRE-LAMINATED MDF(MEDIUM DESNSITY FIBER) BOARD BOTH SIDES LAMINATE Color specs: TBD Leg: MS+ALUMINUM LEG WITH POWDER COATING Color specs: TBD Electrification: Color specs: TBD Screen: 4+4MM SANDWICHED BACK PAINTED MAGNETIC GLASS SCREEN Color specs: TBD | S26: RENDER 2 : FLEXI SHARING GLASS | T26: =INDIRECT("'CALC FLX WST'!R"&(ROW()-3)*7) -> 14400 | U26: =T26*0.9 -> 12960 | V26: =T26*0.85 -> 12240 | W26: =T26*0.8 -> 11520 | X26: =T26*0.7 -> 10080
B27: W | C27: FLX | D27: LNR | E27: SH | F27: PLM | G27: 1200 | H27: X | I27: =CONCATENATE(B27,C27,"-",D27,"-",E27,"-",F27,"-",G27,"-",H27) -> WFLX-LNR-SH-PLM-1200-X | J27: WORKSTATION | K27: FLEXI | L27: LINEAR | M27: SHARING | N27: 1200 | O27: PLMDF BSL | P27: NONE | Q27: {="Actual size: "&N27&" x 600mm per user"&CHAR(10)&CHAR(10)&"Formation - "&K27&" "&M27&CHAR(10)&CHAR(10)&"Top material: "&INDEX('MASTER DATA'!$D$21:$D$29,MATCH(O27,'MASTER DATA'!$B$21:$B$29,0))&CHAR(10)&"Color specs: TBD"&CHAR(10)&CHAR(10)&"Leg: "&INDEX('MASTER DATA'!$D$33:$D$37,MATCH(K27,'MASTER DATA'!$B$33:$B$37,0))&CHAR(10)&"Color specs: TBD"&CHAR(10)&CHAR(10)&"Electrification: "&'MASTER DATA'!D65&CHAR(10)&"Color specs: TBD"&CHAR(10)&CHAR(10)&"Screen: "&INDEX('MASTER DATA'!$D$52:$D$54,MATCH(P27,'MASTER DATA'!$B$52:$B$54,0))&CHAR(10)&"Color specs: TBD"} -> Actual size: 1200 x 600mm per user Formation - FLEXI SHARING Top material: 18MM PRE-LAMINATED MDF(MEDIUM DESNSITY FIBER) BOARD BOTH SIDES LAMINATE Color specs: TBD Leg: MS+ALUMINUM LEG WITH POWDER COATING Color specs: TBD Electrification: Color specs: TBD Screen: Color specs: TBD | S27: RENDER 3 : FLEXI SHARING NO SCREEN | T27: =INDIRECT("'CALC FLX WST'!R"&(ROW()-3)*7) -> 11800 | U27: =T27*0.9 -> 10620 | V27: =T27*0.85 -> 10030 | W27: =T27*0.8 -> 9440 | X27: =T27*0.7 -> 8260
B28: W | C28: FLX | D28: LNR | E28: SH | F28: PoLM | G28: 1200 | H28: F | I28: =CONCATENATE(B28,C28,"-",D28,"-",E28,"-",F28,"-",G28,"-",H28) -> WFLX-LNR-SH-PoLM-1200-F | J28: WORKSTATION | K28: FLEXI | L28: LINEAR | M28: SHARING | N28: 1200 | O28: PoLMDF | P28: FABRIC | Q28: {="Actual size: "&N28&" x 600mm per user"&CHAR(10)&CHAR(10)&"Formation - "&K28&" "&M28&CHAR(10)&CHAR(10)&"Top material: "&INDEX('MASTER DATA'!$D$21:$D$29,MATCH(O28,'MASTER DATA'!$B$21:$B$29,0))&CHAR(10)&"Color specs: TBD"&CHAR(10)&CHAR(10)&"Leg: "&INDEX('MASTER DATA'!$D$33:$D$37,MATCH(K28,'MASTER DATA'!$B$33:$B$37,0))&CHAR(10)&"Color specs: TBD"&CHAR(10)&CHAR(10)&"Electrification: "&'MASTER DATA'!D66&CHAR(10)&"Color specs: TBD"&CHAR(10)&CHAR(10)&"Screen: "&INDEX('MASTER DATA'!$D$52:$D$54,MATCH(P28,'MASTER DATA'!$B$52:$B$54,0))&CHAR(10)&"Color specs: TBD"} -> Actual size: 1200 x 600mm per user Formation - FLEXI SHARING Top material: 18MM POST-LAMINATED MDF(MEDIUM DESNSITY FIBER) BOARD BOTH SIDES LAMINATE Color specs: TBD Leg: MS+ALUMINUM LEG WITH POWDER COATING Color specs: TBD Electrification: Color specs: TBD Screen: L:6" LESS THAN TOP LENGTH, H400mm, D30mm FABRIC PINUP BOARD WITH ALUMINUM TRIMS Color specs: TBD | S28: RENDER 1 : FLEXI SHARING FABRIC | T28: =INDIRECT("'CALC FLX WST'!R"&(ROW()-3)*7) -> 20600 | U28: =T28*0.9 -> 18540 | V28: =T28*0.85 -> 17510 | W28: =T28*0.8 -> 16480 | X28: =T28*0.7 -> 14420
B29: W | C29: FLX | D29: LNR | E29: SH | F29: PoLM | G29: 1200 | H29: G | I29: =CONCATENATE(B29,C29,"-",D29,"-",E29,"-",F29,"-",G29,"-",H29) -> WFLX-LNR-SH-PoLM-1200-G | J29: WORKSTATION | K29: FLEXI | L29: LINEAR | M29: SHARING | N29: 1200 | O29: PoLMDF | P29: GLASS | Q29: {="Actual size: "&N29&" x 600mm per user"&CHAR(10)&CHAR(10)&"Formation - "&K29&" "&M29&CHAR(10)&CHAR(10)&"Top material: "&INDEX('MASTER DATA'!$D$21:$D$29,MATCH(O29,'MASTER DATA'!$B$21:$B$29,0))&CHAR(10)&"Color specs: TBD"&CHAR(10)&CHAR(10)&"Leg: "&INDEX('MASTER DATA'!$D$33:$D$37,MATCH(K29,'MASTER DATA'!$B$33:$B$37,0))&CHAR(10)&"Color specs: TBD"&CHAR(10)&CHAR(10)&"Electrification: "&'MASTER DATA'!D67&CHAR(10)&"Color specs: TBD"&CHAR(10)&CHAR(10)&"Screen: "&INDEX('MASTER DATA'!$D$52:$D$54,MATCH(P29,'MASTER DATA'!$B$52:$B$54,0))&CHAR(10)&"Color specs: TBD"} -> Actual size: 1200 x 600mm per user Formation - FLEXI SHARING Top material: 18MM POST-LAMINATED MDF(MEDIUM DESNSITY FIBER) BOARD BOTH SIDES LAMINATE Color specs: TBD Leg: MS+ALUMINUM LEG WITH POWDER COATING Color specs: TBD Electrification: Color specs: TBD Screen: 4+4MM SANDWICHED BACK PAINTED MAGNETIC GLASS SCREEN Color specs: TBD | S29: RENDER 2 : FLEXI SHARING GLASS | T29: =INDIRECT("'CALC FLX WST'!R"&(ROW()-3)*7) -> 20900 | U29: =T29*0.9 -> 18810 | V29: =T29*0.85 -> 17765 | W29: =T29*0.8 -> 16720 | X29: =T29*0.7 -> 14630
B30: W | C30: FLX | D30: LNR | E30: SH | F30: PoLM | G30: 1200 | H30: X | I30: =CONCATENATE(B30,C30,"-",D30,"-",E30,"-",F30,"-",G30,"-",H30) -> WFLX-LNR-SH-PoLM-1200-X | J30: WORKSTATION | K30: FLEXI | L30: LINEAR | M30: SHARING | N30: 1200 | O30: PoLMDF | P30: NONE | Q30: {="Actual size: "&N30&" x 600mm per user"&CHAR(10)&CHAR(10)&"Formation - "&K30&" "&M30&CHAR(10)&CHAR(10)&"Top material: "&INDEX('MASTER DATA'!$D$21:$D$29,MATCH(O30,'MASTER DATA'!$B$21:$B$29,0))&CHAR(10)&"Color specs: TBD"&CHAR(10)&CHAR(10)&"Leg: "&INDEX('MASTER DATA'!$D$33:$D$37,MATCH(K30,'MASTER DATA'!$B$33:$B$37,0))&CHAR(10)&"Color specs: TBD"&CHAR(10)&CHAR(10)&"Electrification: "&'MASTER DATA'!D68&CHAR(10)&"Color specs: TBD"&CHAR(10)&CHAR(10)&"Screen: "&INDEX('MASTER DATA'!$D$52:$D$54,MATCH(P30,'MASTER DATA'!$B$52:$B$54,0))&CHAR(10)&"Color specs: TBD"} -> Actual size: 1200 x 600mm per user Formation - FLEXI SHARING Top material: 18MM POST-LAMINATED MDF(MEDIUM DESNSITY FIBER) BOARD BOTH SIDES LAMINATE Color specs: TBD Leg: MS+ALUMINUM LEG WITH POWDER COATING Color specs: TBD Electrification: Color specs: TBD Screen: Color specs: TBD | S30: RENDER 3 : FLEXI SHARING NO SCREEN | T30: =INDIRECT("'CALC FLX WST'!R"&(ROW()-3)*7) -> 18300 | U30: =T30*0.9 -> 16470 | V30: =T30*0.85 -> 15555 | W30: =T30*0.8 -> 14640 | X30: =T30*0.7 -> 12810
B31: W | C31: FLX | D31: LNR | E31: SH | F31: LVM | G31: 1200 | H31: F | I31: =CONCATENATE(B31,C31,"-",D31,"-",E31,"-",F31,"-",G31,"-",H31) -> WFLX-LNR-SH-LVM-1200-F | J31: WORKSTATION | K31: FLEXI | L31: LINEAR | M31: SHARING | N31: 1200 | O31: LUVIH-MDF | P31: FABRIC | S31: RENDER 1 : FLEXI SHARING FABRIC | T31: =INDIRECT("'CALC FLX WST'!R"&(ROW()-3)*7) -> 23500 | U31: =T31*0.9 -> 21150 | V31: =T31*0.85 -> 19975 | W31: =T31*0.8 -> 18800 | X31: =T31*0.7 -> 16450
B32: W | C32: FLX | D32: LNR | E32: SH | F32: LVM | G32: 1200 | H32: G | I32: =CONCATENATE(B32,C32,"-",D32,"-",E32,"-",F32,"-",G32,"-",H32) -> WFLX-LNR-SH-LVM-1200-G | J32: WORKSTATION | K32: FLEXI | L32: LINEAR | M32: SHARING | N32: 1200 | O32: LUVIH-MDF | P32: GLASS | S32: RENDER 2 : FLEXI SHARING GLASS | T32: =INDIRECT("'CALC FLX WST'!R"&(ROW()-3)*7) -> 23800 | U32: =T32*0.9 -> 21420 | V32: =T32*0.85 -> 20230 | W32: =T32*0.8 -> 19040 | X32: =T32*0.7 -> 16660
B33: W | C33: FLX | D33: LNR | E33: SH | F33: LVM | G33: 1200 | H33: X | I33: =CONCATENATE(B33,C33,"-",D33,"-",E33,"-",F33,"-",G33,"-",H33) -> WFLX-LNR-SH-LVM-1200-X | J33: WORKSTATION | K33: FLEXI | L33: LINEAR | M33: SHARING | N33: 1200 | O33: LUVIH-MDF | P33: NONE | S33: RENDER 3 : FLEXI SHARING NO SCREEN | T33: =INDIRECT("'CALC FLX WST'!R"&(ROW()-3)*7) -> 21200 | U33: =T33*0.9 -> 19080 | V33: =T33*0.85 -> 18020 | W33: =T33*0.8 -> 16960 | X33: =T33*0.7 -> 14840
B34: W | C34: FLX | D34: LNR | E34: SH | F34: LVP | G34: 1200 | H34: F | I34: =CONCATENATE(B34,C34,"-",D34,"-",E34,"-",F34,"-",G34,"-",H34) -> WFLX-LNR-SH-LVP-1200-F | J34: WORKSTATION | K34: FLEXI | L34: LINEAR | M34: SHARING | N34: 1200 | O34: LUVIH-PLY | P34: FABRIC | S34: RENDER 1 : FLEXI SHARING FABRIC | T34: =INDIRECT("'CALC FLX WST'!R"&(ROW()-3)*7) -> 24900 | U34: =T34*0.9 -> 22410 | V34: =T34*0.85 -> 21165 | W34: =T34*0.8 -> 19920 | X34: =T34*0.7 -> 17430
B35: W | C35: FLX | D35: LNR | E35: SH | F35: LVP | G35: 1200 | H35: G | I35: =CONCATENATE(B35,C35,"-",D35,"-",E35,"-",F35,"-",G35,"-",H35) -> WFLX-LNR-SH-LVP-1200-G | J35: WORKSTATION | K35: FLEXI | L35: LINEAR | M35: SHARING | N35: 1200 | O35: LUVIH-PLY | P35: GLASS | S35: RENDER 2 : FLEXI SHARING GLASS | T35: =INDIRECT("'CALC FLX WST'!R"&(ROW()-3)*7) -> 25200 | U35: =T35*0.9 -> 22680 | V35: =T35*0.85 -> 21420 | W35: =T35*0.8 -> 20160 | X35: =T35*0.7 -> 17640
B36: W | C36: FLX | D36: LNR | E36: SH | F36: LVP | G36: 1200 | H36: X | I36: =CONCATENATE(B36,C36,"-",D36,"-",E36,"-",F36,"-",G36,"-",H36) -> WFLX-LNR-SH-LVP-1200-X | J36: WORKSTATION | K36: FLEXI | L36: LINEAR | M36: SHARING | N36: 1200 | O36: LUVIH-PLY | P36: NONE | S36: RENDER 3 : FLEXI SHARING NO SCREEN | T36: =INDIRECT("'CALC FLX WST'!R"&(ROW()-3)*7) -> 22600 | U36: =T36*0.9 -> 20340 | V36: =T36*0.85 -> 19210 | W36: =T36*0.8 -> 18080 | X36: =T36*0.7 -> 15820
B37: W | C37: FLX | D37: LNR | E37: SH | F37: MB | G37: 1200 | H37: F | I37: =CONCATENATE(B37,C37,"-",D37,"-",E37,"-",F37,"-",G37,"-",H37) -> WFLX-LNR-SH-MB-1200-F | J37: WORKSTATION | K37: FLEXI | L37: LINEAR | M37: SHARING | N37: 1200 | O37: MEMBRANE | P37: FABRIC | S37: RENDER 1 : FLEXI SHARING FABRIC | T37: =INDIRECT("'CALC FLX WST'!R"&(ROW()-3)*7) -> 33200 | U37: =T37*0.9 -> 29880 | V37: =T37*0.85 -> 28220 | W37: =T37*0.8 -> 26560 | X37: =T37*0.7 -> 23240
B38: W | C38: FLX | D38: LNR | E38: SH | F38: MB | G38: 1200 | H38: G | I38: =CONCATENATE(B38,C38,"-",D38,"-",E38,"-",F38,"-",G38,"-",H38) -> WFLX-LNR-SH-MB-1200-G | J38: WORKSTATION | K38: FLEXI | L38: LINEAR | M38: SHARING | N38: 1200 | O38: MEMBRANE | P38: GLASS | S38: RENDER 2 : FLEXI SHARING GLASS | T38: =INDIRECT("'CALC FLX WST'!R"&(ROW()-3)*7) -> 33500 | U38: =T38*0.9 -> 30150 | V38: =T38*0.85 -> 28475 | W38: =T38*0.8 -> 26800 | X38: =T38*0.7 -> 23450
B39: W | C39: FLX | D39: LNR | E39: SH | F39: MB | G39: 1200 | H39: X | I39: =CONCATENATE(B39,C39,"-",D39,"-",E39,"-",F39,"-",G39,"-",H39) -> WFLX-LNR-SH-MB-1200-X | J39: WORKSTATION | K39: FLEXI | L39: LINEAR | M39: SHARING | N39: 1200 | O39: MEMBRANE | P39: NONE | S39: RENDER 3 : FLEXI SHARING NO SCREEN | T39: =INDIRECT("'CALC FLX WST'!R"&(ROW()-3)*7) -> 30900 | U39: =T39*0.9 -> 27810 | V39: =T39*0.85 -> 26265 | W39: =T39*0.8 -> 24720 | X39: =T39*0.7 -> 21630
B40: W | C40: FLX | D40: LNR | E40: SH | F40: PB | G40: 1500 | H40: F | I40: =CONCATENATE(B40,C40,"-",D40,"-",E40,"-",F40,"-",G40,"-",H40) -> WFLX-LNR-SH-PB-1500-F | J40: WORKSTATION | K40: FLEXI | L40: LINEAR | M40: SHARING | N40: 1500 | O40: PLPB BSL | P40: FABRIC | S40: RENDER 1 : FLEXI SHARING FABRIC | T40: =INDIRECT("'CALC FLX WST'!R"&(ROW()-3)*7) -> 14700 | U40: =T40*0.9 -> 13230 | V40: =T40*0.85 -> 12495 | W40: =T40*0.8 -> 11760 | X40: =T40*0.7 -> 10290
B41: W | C41: FLX | D41: LNR | E41: SH | F41: PB | G41: 1500 | H41: G | I41: =CONCATENATE(B41,C41,"-",D41,"-",E41,"-",F41,"-",G41,"-",H41) -> WFLX-LNR-SH-PB-1500-G | J41: WORKSTATION | K41: FLEXI | L41: LINEAR | M41: SHARING | N41: 1500 | O41: PLPB BSL | P41: GLASS | S41: RENDER 2 : FLEXI SHARING GLASS | T41: =INDIRECT("'CALC FLX WST'!R"&(ROW()-3)*7) -> 15200 | U41: =T41*0.9 -> 13680 | V41: =T41*0.85 -> 12920 | W41: =T41*0.8 -> 12160 | X41: =T41*0.7 -> 10640
...

Sheet MASTER DATA
B2: TOPS | C2: RATE/SQM | D2: LEGS | E2: RATE/LEG | F2: ELEC | G2: RATE/PCS | H2: RISER | I2: RATE/PCS | J2: SCREEN | K2: RATE/SQM | L2: SIDE UNITS
B3: PLPB BSL | C3: 2200 | D3: FLEXI 600 | E3: 1800 | F3: NETBOX | G3: 1500 | H3: MINI RISER | I3: 1000 | J3: FABRIC | K3: 4800 | L3: ECO | M3: 1000
B4: PLMDF BSL | C4: 3000 | D4: FLEXI 900 | E4: 1900 | F4: FLAP+PLATE | G4: 1000 | H4: BIG RISER | I4: 4000 | J4: GLASS | K4: 5500 | L4: LUX | M4: 1500
B5: PoLMDF | C5: 7500 | D5: FLEXI 1200 | E5: 2100 | F5: Q CURVY POP | G5: 12500 | H5: VERTEBRAE | I5: 1500 | J5: NONE | K5: 0
B6: LUVIHMDF | C6: 9500 | D6: STARTEK 600 | E6: 3800 | F6: CHINA MODULE | G6: 2000
B7: LIVIHPLY | C7: 10500 | D7: STARTEK 900 | E7: 4000 | F7: 2 WAY | G7: 3500
B8: VENEER | C8: 30000 | D8: STARTEK 1200 | E8: 4200
B9: GLASS | C9: 7500 | D9: LOOP | E9: 12500
B10: MEMBRANE | C10: 16250 | D10: ATHENA | E10: 15000
B11: MARBLE | C11: =60000/1.6 -> 37500 | D11: FLUTED WOOD | E11: 20000
D12: PANELS | E12: 6000
B16: MARGIN MULTIPLIER | C16: 2
B19: TOPS
B20: ABBREVIATION | C20: SKU CODE | D20: FULL NAME
B21: PLPB BSL | C21: PB | D21: 18MM PRE-LAMINATED PARTICLE BOARD BOTH SIDES LAMINATE WITH EDGEBANDING
B22: PLMDF BSL | C22: PLM | D22: 18MM PRE-LAMINATED MDF(MEDIUM DESNSITY FIBER) BOARD BOTH SIDES LAMINATE
B23: PoLMDF | C23: PoLM | D23: 18MM POST-LAMINATED MDF(MEDIUM DESNSITY FIBER) BOARD BOTH SIDES LAMINATE
B24: LUVIHMDF | C24: LVM | D24: 18MM MERNIO LUVIH POST-LAMINATED MDF(MEDIUM DESNSITY FIBER) BOARD, BOTTOM SIDE BALANCING LAMINATE
B25: LIVIHPLY | C25: LVP | D25: 25MM LUVIH POST-LAMINATED PLY (BIRCH/COMMERCIAL)
B26: VENEER | C26: VNR | D26: 40MM WOOD VENEERS ON PLY
B27: GLASS | C27: GL | D27: 10MM EXTRA TOUGHENED BACK PAINTED / CLEAR GLASS
B28: MEMBRANE | C28: MB | D28: 25MM GERMAN MEMBRANE ON POST-LAMINATED MDF(MEDIUM DESNSITY FIBER) BOARD
B29: MARBLE | C29: MBL | D29: 10MM MARBLE ON POST-LAMINATED MDF(MEDIUM DESNSITY FIBER) BOARD
B31: LEGS
B32: ABBREVIATION | C32: SKU CODE | D32: FULL NAME
B33: FLEXI | C33: FLX | D33: MS+ALUMINUM LEG WITH POWDER COATING
B34: STARTEK | C34: STK | D34: ALUMINUM LEG WITH POWDER COATING
B35: LOOP | C35: LP | D35: ALUMINUM LEG WITH CHROME/TITANIUM/RAW/PC FINISH
B36: ATHENA | C36: ATH | D36: SS LEG WITH PVD COATING
B37: FLUTED WOOD | C37: FLW | D37: FLUTED VENEER ON MDF LEG
B39: ELECTRIFICATION
B40: ABBREVIATION | D40: FULL NAME
B41: NETBOX | D41: 8/10/12 MODULE NETBOX
B42: FLAP+PLATE | D42: 450MM XIO FLAP + SWITCH PLATE INSIDE, *switches not in Burosys scope
B43: Q CURVY POP | D43: Q CURVY POP BOX
B44: CHINA MODULE | D44: 4+4 SWITCHES WITH SCREEN HOLDER
B45: 2 WAY | D45: 2 WAY ACCESS FLAP WITH SWITCH PLATE INSIDE
B46: MINI RISER | D46: 100MM VERTICAL BOX
B47: BIG RISER | D47: 450MM VERTICAL BOX
B48: VERTEBRAE | D48: VERTEBRA SNAKE
...

Sheet CALC FLX WST
A1: CALC
A2: =PRICELIST!I4 -> WFLX-LNR-SH-PB-900-F
A3: users | B3: length | C3: w | D3: total top | E3: 1200 | F3: 900 | G3: 600 | H3: beam/mts | I3: total screen | J3: ele modty | K3: labour | L3: raceway | M3: a flap | N3: Leg Apron | O3: total | P3: per/psn | Q3: profit | R3: rounding
E4: ='MASTER DATA'!E5 -> 2100 | F4: ='MASTER DATA'!E4 -> 1900 | G4: ='MASTER DATA'!E3 -> 1800 | H4: 380 | I4: ='MASTER DATA'!K3 -> 4800 | J4: ='MASTER DATA'!I3 -> 1000 | K4: 375 | L4: 585 | M4: ='MASTER DATA'!G4 -> 1000 | N4: 3300 | Q4: ='MASTER DATA'!C16 -> 2
A5: 6 | B5: =0.9*3 -> 2.7 | C5: 1.2 | D5: =B5*C5 -> 3.24 | I5: =B5*0.4 -> 1.08 | J5: 2 | K5: =A5 -> 6 | L5: =B5 -> 2.7 | M5: =A5 -> 6 | N5: =(1.2*0.4)*2 -> 0.96
D6: ='MASTER DATA'!C3 -> 2200 | E6: 2 | F6: 0 | G6: 0 | H6: =B5*2 -> 5.4
D7: =D5*D6 -> 7128 | E7: =E6*E4 -> 4200 | F7: =F4*F6 -> 0 | G7: =G4*G6 -> 0 | H7: =H4*H6 -> 2052 | I7: =I4*I5 -> 5184 | J7: =J4*J5 -> 2000 | K7: =K4*K5 -> 2250 | L7: =L4*L5 -> 1579.5 | M7: =M4*M5 -> 6000 | N7: =N4*N5 -> 3168 | O7: =SUM(D7:N7) -> 33561.5 | P7: =O7/A5 -> 5593.5833 | Q7: =P7*Q4 -> 11187.167 | R7: =MROUND(Q7,100) -> 11200
A9: =PRICELIST!I5 -> WFLX-LNR-SH-PB-900-G
A10: users | B10: length | C10: w | D10: total top | E10: 1200 | F10: 900 | G10: 600 | H10: beam/mts | I10: total screen | J10: ele modty | K10: labour | L10: raceway | M10: a flap | N10: Leg Apron | O10: total | P10: per/psn | Q10: profit | R10: rounding
E11: =E4 -> 2100 | F11: =F4 -> 1900 | G11: =G4 -> 1800 | H11: =H4 -> 380 | I11: ='MASTER DATA'!K4 -> 5500 | J11: =J4 -> 1000 | K11: =K4 -> 375 | L11: =L4 -> 585 | M11: =M4 -> 1000 | N11: =N4 -> 3300 | O11: =O4 -> 0 | P11: =P4 -> 0 | Q11: =Q4 -> 2 | R11: =R4 -> 0
A12: 6 | B12: =0.9*3 -> 2.7 | C12: 1.2 | D12: =B12*C12 -> 3.24 | I12: =B12*0.4 -> 1.08 | J12: 2 | K12: =A12 -> 6 | L12: =B12 -> 2.7 | M12: =A12 -> 6 | N12: =(1.2*0.4)*2 -> 0.96
D13: =D6 -> 2200 | E13: 2 | F13: 0 | G13: 0 | H13: =B12*2 -> 5.4
D14: =D12*D13 -> 7128 | E14: =E13*E11 -> 4200 | F14: =F11*F13 -> 0 | G14: =G11*G13 -> 0 | H14: =H11*H13 -> 2052 | I14: =I11*I12 -> 5940 | J14: =J11*J12 -> 2000 | K14: =K11*K12 -> 2250 | L14: =L11*L12 -> 1579.5 | M14: =M11*M12 -> 6000 | N14: =N11*N12 -> 3168 | O14: =SUM(D14:N14) -> 34317.5 | P14: =O14/A12 -> 5719.5833 | Q14: =P14*Q11 -> 11439.167 | R14: =MROUND(Q14,100) -> 11400
Q15: =Q8 -> 0
A16: =PRICELIST!I6 -> WFLX-LNR-SH-PB-900-X
A17: users | B17: length | C17: w | D17: total top | E17: 1200 | F17: 900 | G17: 600 | H17: beam/mts | I17: total screen | J17: ele modty | K17: labour | L17: raceway | M17: a flap | N17: Leg Apron | O17: total | P17: per/psn | Q17: profit | R17: rounding
A18: =A11 -> 0 | B18: =B11 -> 0 | C18: =C11 -> 0 | D18: =D11 -> 0 | E18: =E11 -> 2100 | F18: =F11 -> 1900 | G18: =G11 -> 1800 | H18: =H11 -> 380 | I18: ='MASTER DATA'!K5 -> 0 | J18: =J11 -> 1000 | K18: =K11 -> 375 | L18: =L11 -> 585 | M18: =M11 -> 1000 | N18: =N11 -> 3300 | O18: =O11 -> 0 | P18: =P11 -> 0 | Q18: =Q11 -> 2
A19: 6 | B19: =0.9*3 -> 2.7 | C19: 1.2 | D19: =B19*C19 -> 3.24 | I19: =B19*0.4 -> 1.08 | J19: 2 | K19: =A19 -> 6 | L19: =B19 -> 2.7 | M19: =A19 -> 6 | N19: =(1.2*0.4)*2 -> 0.96
D20: =D13 -> 2200 | E20: 2 | F20: 0 | G20: 0 | H20: =B19*2 -> 5.4
D21: =D19*D20 -> 7128 | E21: =E20*E18 -> 4200 | F21: =F18*F20 -> 0 | G21: =G18*G20 -> 0 | H21: =H18*H20 -> 2052 | I21: =I18*I19 -> 0 | J21: =J18*J19 -> 2000 | K21: =K18*K19 -> 2250 | L21: =L18*L19 -> 1579.5 | M21: =M18*M19 -> 6000 | N21: =N18*N19 -> 3168 | O21: =SUM(D21:N21) -> 28377.5 | P21: =O21/A19 -> 4729.5833 | Q21: =P21*Q18 -> 9459.1667 | R21: =MROUND(Q21,100) -> 9500
A23: =PRICELIST!I7 -> WFLX-LNR-SH-PLM-900-F
A24: users | B24: length | C24: w | D24: total top | E24: 1200 | F24: 900 | G24: 600 | H24: beam/mts | I24: total screen | J24: ele modty | K24: labour | L24: raceway | M24: a flap | N24: Leg Apron | O24: total | P24: per/psn | Q24: profit | R24: rounding
A25: =A18 -> 0 | B25: =B18 -> 0 | C25: =C18 -> 0 | D25: =D18 -> 0 | E25: =E18 -> 2100 | F25: =F18 -> 1900 | G25: =G18 -> 1800 | H25: =H18 -> 380 | I25: =I4 -> 4800 | J25: =J18 -> 1000 | K25: =K18 -> 375 | L25: =L18 -> 585 | M25: =M18 -> 1000 | N25: =N18 -> 3300 | O25: =O18 -> 0 | P25: =P18 -> 0 | Q25: =Q18 -> 2
A26: 6 | B26: =0.9*3 -> 2.7 | C26: 1.2 | D26: =B26*C26 -> 3.24 | I26: =B26*0.4 -> 1.08 | J26: 2 | K26: =A26 -> 6 | L26: =B26 -> 2.7 | M26: =A26 -> 6 | N26: =(1.2*0.4)*2 -> 0.96
D27: ='MASTER DATA'!C4 -> 3000 | E27: 2 | F27: 0 | G27: 0 | H27: =B26*2 -> 5.4
D28: =D26*D27 -> 9720 | E28: =E27*E25 -> 4200 | F28: =F25*F27 -> 0 | G28: =G25*G27 -> 0 | H28: =H25*H27 -> 2052 | I28: =I25*I26 -> 5184 | J28: =J25*J26 -> 2000 | K28: =K25*K26 -> 2250 | L28: =L25*L26 -> 1579.5 | M28: =M25*M26 -> 6000 | N28: =N25*N26 -> 3168 | O28: =SUM(D28:N28) -> 36153.5 | P28: =O28/A26 -> 6025.5833 | Q28: =P28*Q25 -> 12051.167 | R28: =MROUND(Q28,100) -> 12100
A30: =PRICELIST!I8 -> WFLX-LNR-SH-PLM-900-G
A31: users | B31: length | C31: w | D31: total top | E31: 1200 | F31: 900 | G31: 600 | H31: beam/mts | I31: total screen | J31: ele modty | K31: labour | L31: raceway | M31: a flap | N31: Leg Apron | O31: total | P31: per/psn | Q31: profit | R31: rounding
A32: =A25 -> 0 | B32: =B25 -> 0 | C32: =C25 -> 0 | D32: =D25 -> 0 | E32: =E25 -> 2100 | F32: =F25 -> 1900 | G32: =G25 -> 1800 | H32: =H25 -> 380 | I32: =I11 -> 5500 | J32: =J25 -> 1000 | K32: =K25 -> 375 | L32: =L25 -> 585 | M32: =M25 -> 1000 | N32: =N25 -> 3300 | O32: =O25 -> 0 | P32: =P25 -> 0 | Q32: =Q25 -> 2
A33: 6 | B33: =0.9*3 -> 2.7 | C33: 1.2 | D33: =B33*C33 -> 3.24 | I33: =B33*0.4 -> 1.08 | J33: 2 | K33: =A33 -> 6 | L33: =B33 -> 2.7 | M33: =A33 -> 6 | N33: =(1.2*0.4)*2 -> 0.96
D34: =D27 -> 3000 | E34: 2 | F34: 0 | G34: 0 | H34: =B33*2 -> 5.4
D35: =D33*D34 -> 9720 | E35: =E34*E32 -> 4200 | F35: =F32*F34 -> 0 | G35: =G32*G34 -> 0 | H35: =H32*H34 -> 2052 | I35: =I32*I33 -> 5940 | J35: =J32*J33 -> 2000 | K35: =K32*K33 -> 2250 | L35: =L32*L33 -> 1579.5 | M35: =M32*M33 -> 6000 | N35: =N32*N33 -> 3168 | O35: =SUM(D35:N35) -> 36909.5 | P35: =O35/A33 -> 6151.5833 | Q35: =P35*Q32 -> 12303.167 | R35: =MROUND(Q35,100) -> 12300
A37: =PRICELIST!I9 -> WFLX-LNR-SH-PLM-900-X
A38: users | B38: length | C38: w | D38: total top | E38: 1200 | F38: 900 | G38: 600 | H38: beam/mts | I38: total screen | J38: ele modty | K38: labour | L38: raceway | M38: a flap | N38: Leg Apron | O38: total | P38: per/psn | Q38: profit | R38: rounding
A39: =A32 -> 0 | B39: =B32 -> 0 | C39: =C32 -> 0 | D39: =D32 -> 0 | E39: =E32 -> 2100 | F39: =F32 -> 1900 | G39: =G32 -> 1800 | H39: =H32 -> 380 | I39: =I18 -> 0 | J39: =J32 -> 1000 | K39: =K32 -> 375 | L39: =L32 -> 585 | M39: =M32 -> 1000 | N39: =N32 -> 3300 | O39: =O32 -> 0 | P39: =P32 -> 0 | Q39: =Q32 -> 2
A40: 6 | B40: =0.9*3 -> 2.7 | C40: 1.2 | D40: =B40*C40 -> 3.24 | I40: =B40*0.4 -> 1.08 | J40: 2 | K40: =A40 -> 6 | L40: =B40 -> 2.7 | M40: =A40 -> 6 | N40: =(1.2*0.4)*2 -> 0.96
D41: =D34 -> 3000 | E41: 2 | F41: 0 | G41: 0 | H41: =B40*2 -> 5.4
D42: =D40*D41 -> 9720 | E42: =E41*E39 -> 4200 | F42: =F39*F41 -> 0 | G42: =G39*G41 -> 0 | H42: =H39*H41 -> 2052 | I42: =I39*I40 -> 0 | J42: =J39*J40 -> 2000 | K42: =K39*K40 -> 2250 | L42: =L39*L40 -> 1579.5 | M42: =M39*M40 -> 6000 | N42: =N39*N40 -> 3168 | O42: =SUM(D42:N42) -> 30969.5 | P42: =O42/A40 -> 5161.5833 | Q42: =P42*Q39 -> 10323.167 | R42: =MROUND(Q42,100) -> 10300
A44: =PRICELIST!I10 -> WFLX-LNR-SH-PoLM-900-F
A45: users | B45: length | C45: w | D45: total top | E45: 1200 | F45: 900 | G45: 600 | H45: beam/mts | I45: total screen | J45: ele modty | K45: labour | L45: raceway | M45: a flap | N45: Leg Apron | O45: total | P45: per/psn | Q45: profit | R45: rounding
...

Sheet CALC STK WST
A1: CALC
A2: =PRICELIST!I216 -> WSTK-LNR-SH-PB-900-F
A3: users | B3: length | C3: w | D3: total top | E3: 1200 | F3: 900 | G3: 600 | H3: beam/mts | I3: total screen | J3: ele modty | K3: labour | L3: raceway | M3: a flap | N3: Leg Apron | O3: total | P3: per/psn | Q3: profit | R3: rounding
E4: ='MASTER DATA'!E8 -> 4200 | F4: ='MASTER DATA'!E7 -> 4000 | G4: ='MASTER DATA'!E6 -> 3800 | H4: 380 | I4: ='MASTER DATA'!K3 -> 4800 | J4: ='MASTER DATA'!I3 -> 1000 | K4: 375 | L4: 585 | M4: ='MASTER DATA'!G4 -> 1000 | N4: 3300 | Q4: ='MASTER DATA'!C16 -> 2
A5: 6 | B5: =0.9*3 -> 2.7 | C5: 1.2 | D5: =B5*C5 -> 3.24 | I5: =B5*0.4 -> 1.08 | J5: 2 | K5: =A5 -> 6 | L5: =B5 -> 2.7 | M5: =A5 -> 6 | N5: =(1.2*0.4)*2 -> 0.96
D6: ='MASTER DATA'!C3 -> 2200 | E6: 2 | F6: 0 | G6: 0 | H6: =B5*2 -> 5.4
D7: =D5*D6 -> 7128 | E7: =E6*E4 -> 8400 | F7: =F4*F6 -> 0 | G7: =G4*G6 -> 0 | H7: =H4*H6 -> 2052 | I7: =I4*I5 -> 5184 | J7: =J4*J5 -> 2000 | K7: =K4*K5 -> 2250 | L7: =L4*L5 -> 1579.5 | M7: =M4*M5 -> 6000 | N7: =N4*N5 -> 3168 | O7: =SUM(D7:N7) -> 37761.5 | P7: =O7/A5 -> 6293.5833 | Q7: =P7*Q4 -> 12587.167 | R7: =MROUND(Q7,100) -> 12600
A9: =PRICELIST!I217 -> WSTK-LNR-SH-PB-900-G
A10: users | B10: length | C10: w | D10: total top | E10: 1200 | F10: 900 | G10: 600 | H10: beam/mts | I10: total screen | J10: ele modty | K10: labour | L10: raceway | M10: a flap | N10: Leg Apron | O10: total | P10: per/psn | Q10: profit | R10: rounding
E11: =E4 -> 4200 | F11: =F4 -> 4000 | G11: =G4 -> 3800 | H11: =H4 -> 380 | I11: ='MASTER DATA'!K4 -> 5500 | J11: =J4 -> 1000 | K11: =K4 -> 375 | L11: =L4 -> 585 | M11: =M4 -> 1000 | N11: =N4 -> 3300 | O11: =O4 -> 0 | P11: =P4 -> 0 | Q11: =Q4 -> 2 | R11: =R4 -> 0
A12: 6 | B12: =0.9*3 -> 2.7 | C12: 1.2 | D12: =B12*C12 -> 3.24 | I12: =B12*0.4 -> 1.08 | J12: 2 | K12: =A12 -> 6 | L12: =B12 -> 2.7 | M12: =A12 -> 6 | N12: =(1.2*0.4)*2 -> 0.96
D13: =D6 -> 2200 | E13: 2 | F13: 0 | G13: 0 | H13: =B12*2 -> 5.4
D14: =D12*D13 -> 7128 | E14: =E13*E11 -> 8400 | F14: =F11*F13 -> 0 | G14: =G11*G13 -> 0 | H14: =H11*H13 -> 2052 | I14: =I11*I12 -> 5940 | J14: =J11*J12 -> 2000 | K14: =K11*K12 -> 2250 | L14: =L11*L12 -> 1579.5 | M14: =M11*M12 -> 6000 | N14: =N11*N12 -> 3168 | O14: =SUM(D14:N14) -> 38517.5 | P14: =O14/A12 -> 6419.5833 | Q14: =P14*Q11 -> 12839.167 | R14: =MROUND(Q14,100) -> 12800
Q15: =Q8 -> 0
A16: =PRICELIST!I218 -> WSTK-LNR-SH-PB-900-X
A17: users | B17: length | C17: w | D17: total top | E17: 1200 | F17: 900 | G17: 600 | H17: beam/mts | I17: total screen | J17: ele modty | K17: labour | L17: raceway | M17: a flap | N17: Leg Apron | O17: total | P17: per/psn | Q17: profit | R17: rounding
A18: =A11 -> 0 | B18: =B11 -> 0 | C18: =C11 -> 0 | D18: =D11 -> 0 | E18: =E11 -> 4200 | F18: =F11 -> 4000 | G18: =G11 -> 3800 | H18: =H11 -> 380 | I18: ='MASTER DATA'!K5 -> 0 | J18: =J11 -> 1000 | K18: =K11 -> 375 | L18: =L11 -> 585 | M18: =M11 -> 1000 | N18: =N11 -> 3300 | O18: =O11 -> 0 | P18: =P11 -> 0 | Q18: =Q11 -> 2
A19: 6 | B19: =0.9*3 -> 2.7 | C19: 1.2 | D19: =B19*C19 -> 3.24 | I19: =B19*0.4 -> 1.08 | J19: 2 | K19: =A19 -> 6 | L19: =B19 -> 2.7 | M19: =A19 -> 6 | N19: =(1.2*0.4)*2 -> 0.96
D20: =D13 -> 2200 | E20: 2 | F20: 0 | G20: 0 | H20: =B19*2 -> 5.4
D21: =D19*D20 -> 7128 | E21: =E20*E18 -> 8400 | F21: =F18*F20 -> 0 | G21: =G18*G20 -> 0 | H21: =H18*H20 -> 2052 | I21: =I18*I19 -> 0 | J21: =J18*J19 -> 2000 | K21: =K18*K19 -> 2250 | L21: =L18*L19 -> 1579.5 | M21: =M18*M19 -> 6000 | N21: =N18*N19 -> 3168 | O21: =SUM(D21:N21) -> 32577.5 | P21: =O21/A19 -> 5429.5833 | Q21: =P21*Q18 -> 10859.167 | R21: =MROUND(Q21,100) -> 10900
A23: =PRICELIST!I219 -> WSTK-LNR-SH-PLM-900-F
A24: users | B24: length | C24: w | D24: total top | E24: 1200 | F24: 900 | G24: 600 | H24: beam/mts | I24: total screen | J24: ele modty | K24: labour | L24: raceway | M24: a flap | N24: Leg Apron | O24: total | P24: per/psn | Q24: profit | R24: rounding
A25: =A18 -> 0 | B25: =B18 -> 0 | C25: =C18 -> 0 | D25: =D18 -> 0 | E25: =E18 -> 4200 | F25: =F18 -> 4000 | G25: =G18 -> 3800 | H25: =H18 -> 380 | I25: =I4 -> 4800 | J25: =J18 -> 1000 | K25: =K18 -> 375 | L25: =L18 -> 585 | M25: =M18 -> 1000 | N25: =N18 -> 3300 | O25: =O18 -> 0 | P25: =P18 -> 0 | Q25: =Q18 -> 2
A26: 6 | B26: =0.9*3 -> 2.7 | C26: 1.2 | D26: =B26*C26 -> 3.24 | I26: =B26*0.4 -> 1.08 | J26: 2 | K26: =A26 -> 6 | L26: =B26 -> 2.7 | M26: =A26 -> 6 | N26: =(1.2*0.4)*2 -> 0.96
D27: ='MASTER DATA'!C4 -> 3000 | E27: 2 | F27: 0 | G27: 0 | H27: =B26*2 -> 5.4
D28: =D26*D27 -> 9720 | E28: =E27*E25 -> 8400 | F28: =F25*F27 -> 0 | G28: =G25*G27 -> 0 | H28: =H25*H27 -> 2052 | I28: =I25*I26 -> 5184 | J28: =J25*J26 -> 2000 | K28: =K25*K26 -> 2250 | L28: =L25*L26 -> 1579.5 | M28: =M25*M26 -> 6000 | N28: =N25*N26 -> 3168 | O28: =SUM(D28:N28) -> 40353.5 | P28: =O28/A26 -> 6725.5833 | Q28: =P28*Q25 -> 13451.167 | R28: =MROUND(Q28,100) -> 13500
A30: =PRICELIST!I220 -> WSTK-LNR-SH-PLM-900-G
A31: users | B31: length | C31: w | D31: total top | E31: 1200 | F31: 900 | G31: 600 | H31: beam/mts | I31: total screen | J31: ele modty | K31: labour | L31: raceway | M31: a flap | N31: Leg Apron | O31: total | P31: per/psn | Q31: profit | R31: rounding
A32: =A25 -> 0 | B32: =B25 -> 0 | C32: =C25 -> 0 | D32: =D25 -> 0 | E32: =E25 -> 4200 | F32: =F25 -> 4000 | G32: =G25 -> 3800 | H32: =H25 -> 380 | I32: =I11 -> 5500 | J32: =J25 -> 1000 | K32: =K25 -> 375 | L32: =L25 -> 585 | M32: =M25 -> 1000 | N32: =N25 -> 3300 | O32: =O25 -> 0 | P32: =P25 -> 0 | Q32: =Q25 -> 2
A33: 6 | B33: =0.9*3 -> 2.7 | C33: 1.2 | D33: =B33*C33 -> 3.24 | I33: =B33*0.4 -> 1.08 | J33: 2 | K33: =A33 -> 6 | L33: =B33 -> 2.7 | M33: =A33 -> 6 | N33: =(1.2*0.4)*2 -> 0.96
D34: =D27 -> 3000 | E34: 2 | F34: 0 | G34: 0 | H34: =B33*2 -> 5.4
D35: =D33*D34 -> 9720 | E35: =E34*E32 -> 8400 | F35: =F32*F34 -> 0 | G35: =G32*G34 -> 0 | H35: =H32*H34 -> 2052 | I35: =I32*I33 -> 5940 | J35: =J32*J33 -> 2000 | K35: =K32*K33 -> 2250 | L35: =L32*L33 -> 1579.5 | M35: =M32*M33 -> 6000 | N35: =N32*N33 -> 3168 | O35: =SUM(D35:N35) -> 41109.5 | P35: =O35/A33 -> 6851.5833 | Q35: =P35*Q32 -> 13703.167 | R35: =MROUND(Q35,100) -> 13700
A37: =PRICELIST!I221 -> WSTK-LNR-SH-PLM-900-X
A38: users | B38: length | C38: w | D38: total top | E38: 1200 | F38: 900 | G38: 600 | H38: beam/mts | I38: total screen | J38: ele modty | K38: labour | L38: raceway | M38: a flap | N38: Leg Apron | O38: total | P38: per/psn | Q38: profit | R38: rounding
A39: =A32 -> 0 | B39: =B32 -> 0 | C39: =C32 -> 0 | D39: =D32 -> 0 | E39: =E32 -> 4200 | F39: =F32 -> 4000 | G39: =G32 -> 3800 | H39: =H32 -> 380 | I39: =I18 -> 0 | J39: =J32 -> 1000 | K39: =K32 -> 375 | L39: =L32 -> 585 | M39: =M32 -> 1000 | N39: =N32 -> 3300 | O39: =O32 -> 0 | P39: =P32 -> 0 | Q39: =Q32 -> 2
A40: 6 | B40: =0.9*3 -> 2.7 | C40: 1.2 | D40: =B40*C40 -> 3.24 | I40: =B40*0.4 -> 1.08 | J40: 2 | K40: =A40 -> 6 | L40: =B40 -> 2.7 | M40: =A40 -> 6 | N40: =(1.2*0.4)*2 -> 0.96
D41: =D34 -> 3000 | E41: 2 | F41: 0 | G41: 0 | H41: =B40*2 -> 5.4
D42: =D40*D41 -> 9720 | E42: =E41*E39 -> 8400 | F42: =F39*F41 -> 0 | G42: =G39*G41 -> 0 | H42: =H39*H41 -> 2052 | I42: =I39*I40 -> 0 | J42: =J39*J40 -> 2000 | K42: =K39*K40 -> 2250 | L42: =L39*L40 -> 1579.5 | M42: =M39*M40 -> 6000 | N42: =N39*N40 -> 3168 | O42: =SUM(D42:N42) -> 35169.5 | P42: =O42/A40 -> 5861.5833 | Q42: =P42*Q39 -> 11723.167 | R42: =MROUND(Q42,100) -> 11700
A44: =PRICELIST!I222 -> WSTK-LNR-SH-PoLM-900-F
A45: users | B45: length | C45: w | D45: total top | E45: 1200 | F45: 900 | G45: 600 | H45: beam/mts | I45: total screen | J45: ele modty | K45: labour | L45: raceway | M45: a flap | N45: Leg Apron | O45: total | P45: per/psn | Q45: profit | R45: rounding
...

Sheet CALC PANEL WST
A1: CALC
A2: =PRICELIST!I414 -> WPNL-LNR-SH-PB-1200
A3: users | B3: length | C3: w | D3: total top | E3: PANELS | F3: beam/mts | G3: labour | H3: total | I3: per/psn | J3: profit | K3: rounding
E4: ='MASTER DATA'!E12 -> 6000 | F4: 380 | G4: 500 | J4: ='MASTER DATA'!C16 -> 2
A5: 6 | B5: =1.2*3 -> 3.6 | C5: =1.2 -> 1.2 | D5: =B5*C5 -> 4.32 | E5: =B5+(((A5/2)+1)*C5) -> 8.4 | G5: =A5 -> 6
D6: ='MASTER DATA'!C3 -> 2200 | E6: 1.2 | F6: =B5*2 -> 7.2
D7: =D5*D6 -> 9504 | E7: =E6*E5*E4 -> 60480 | F7: =F4*F6 -> 2736 | G7: =G4*G5 -> 3000 | H7: =SUM(D7:G7) -> 75720 | I7: =H7/A5 -> 12620 | J7: =I7*J4 -> 25240 | K7: =MROUND(J7,100) -> 25200
A9: =PRICELIST!I415 -> WPNL-LNR-NSH-PB-1200
A10: users | B10: length | C10: w | D10: total top | E10: PANELS | F10: beam/mts | G10: labour | H10: total | I10: per/psn | J10: profit | K10: rounding
E11: =E4 -> 6000 | F11: 380 | G11: 500 | J11: =J4 -> 2
A12: 3 | B12: =1.2*3 -> 3.6 | C12: 0.6 | D12: =B12*C12 -> 2.16 | E12: =B12+(((A12/2)+1)*C12) -> 5.1 | G12: =A12 -> 3
D13: =D6 -> 2200 | E13: 1.2 | F13: =B12*2 -> 7.2
D14: =D12*D13 -> 4752 | E14: =E13*E12*E11 -> 36720 | F14: =F11*F13 -> 2736 | G14: =G11*G12 -> 1500 | H14: =SUM(D14:G14) -> 45708 | I14: =H14/A12 -> 15236 | J14: =I14*J11 -> 30472 | K14: =MROUND(J14,100) -> 30500
J15: =J8 -> 0
A16: =PRICELIST!I416 -> WPNL-LNR-SU-PB-1200
A17: users | B17: length | C17: w | D17: total top | E17: PANELS | F17: beam/mts | G17: labour | H17: total | I17: per/psn | J17: profit | K17: rounding
E18: =E11 -> 6000 | F18: 380 | G18: 500 | J18: =J11 -> 2
A19: 1 | B19: 1.2 | C19: 0.6 | D19: =B19*C19 -> 0.72 | E19: =(C19*2)+B19 -> 2.4 | G19: =A19 -> 1
D20: =D13 -> 2200 | E20: 1.2 | F20: =B19*2 -> 2.4
D21: =D19*D20 -> 1584 | E21: =E20*E19*E18 -> 17280 | F21: =F18*F20 -> 912 | G21: =G18*G19 -> 500 | H21: =SUM(D21:G21) -> 20276 | I21: =H21/A19 -> 20276 | J21: =I21*J18 -> 40552 | K21: =MROUND(J21,100) -> 40600
A23: =PRICELIST!I417 -> WPNL-LNR-SH-PB-1500
A24: users | B24: length | C24: w | D24: total top | E24: PANELS | F24: beam/mts | G24: labour | H24: total | I24: per/psn | J24: profit | K24: rounding
E25: =E18 -> 6000 | F25: 380 | G25: 500 | J25: =J18 -> 2
A26: 6 | B26: 4.5 | C26: =1.2 -> 1.2 | D26: =B26*C26 -> 5.4 | E26: =B26+(((A26/2)+1)*C26) -> 9.3 | G26: =A26 -> 6
D27: =D20 -> 2200 | E27: 1.2 | F27: =B26*2 -> 9
